Workbook

Sheet 假設參數
B1: Mathify Labs — 假設參數儀表板
B3: 定價與營收假設
B4: 參數 | C4: 數值 | D4: 單位 | E4: 說明
B5: 月費 | C5: 600 | D5: NT$/月 | E5: 付費用戶每月訂閱費
B6: 年繳折扣 | C6: 0.83 | E6: 年繳方案為月費 × 10（83折）
B7: 年繳用戶占比 | C7: 0 | E7: 目前假設 0%，可調整
B8: ARPPU（付費用戶月均） | C8: =C5*(1-C7*(1-C6)) | D8: NT$/月 | E8: 考慮年繳折扣後的付費用戶實際月均收入
B9: 免費→付費轉換率 | C9: 0.033 | E9: Year 1 目標：500 付費 / 15,000 總用戶 ≈ 3.3%
B11: 每用戶變動成本（COGS）
B12: 成本項目 | C12: 數值 | D12: 單位 | E12: 說明
B13: AI 推理成本 | C13: 100 | D13: NT$/月/用戶 | E13: 平均 150 次查詢/月 × NT$0.6/次
B14: 雲端基礎設施 | C14: 20 | D14: NT$/月/用戶 | E14: 伺服器、CDN、資料庫分攤
B15: COGS 合計 | C15: =C13+C14 | D15: NT$/月/用戶
B17: 客戶生命週期假設
B18: 學生類型 | C18: 占比 | D18: 留存月數 | E18: 說明
B19: 短期使用（1 學年） | C19: 0.6 | D19: 10 | E19: 段考/會考衝刺後離開
B20: 中期使用（2 學年） | C20: 0.3 | D20: 20 | E20: 跨學年持續訂閱
B21: 長期使用（3 年+） | C21: 0.1 | D21: 30 | E21: 國中→高中續用
B22: 加權平均生命週期 | C22: =SUMPRODUCT(C19:C21,D19:D21) | D22: 個月
B23: 保守調整係數 | C23: 0.93 | E23: 考量寒暑假流失，15→14 個月 ≈ 93%
B24: 調整後生命週期 | C24: =ROUND(C22*C23,0) | D24: 個月
B26: CAC（獲客成本）假設
B27: 獲客渠道 | C27: CAC | D27: 占比 | E27: 說明
B28: 免費轉付費（PLG） | C28: 100 | D28: 0.4 | E28: 免費用戶自然轉換
B29: 口碑推薦 | C29: 400 | D29: 0.25 | E29: 推薦獎勵機制
B30: KOL / 社群行銷 | C30: 1000 | D30: 0.2 | E30: 數學補教 YouTuber 合作
B31: 校園推廣 | C31: 650 | D31: 0.15 | E31: 教育展、學校免費試用
B32: 加權平均 CAC | C32: =SUMPRODUCT(C28:C31,D28:D31) | D32: NT$
B33: CAC 緩衝（含測試成本） | C33: 60 | E33: 渠道測試與優化額外支出
B34: 最終 CAC | C34: =C32+C33
B36: 用戶成長假設
B37: 年度 | C37: 付費用戶數 | D37: 免費用戶數（年底） | E37: 付費啟動月
B38: Year 1 | C38: 500 | D38: 15000 | E38: 6
B39: Year 2 | C39: 2000 | D39: 40000 | E39: 1
B40: Year 3 | C40: 5000 | D40: 80000 | E40: 1
B41: 實際轉換率（驗算） | C41: =IF(C38+D38=0,0,C38/(C38+D38)) | D41: =IF(C39+D39=0,0,C39/(C39+D39)) | E41: =IF(C40+D40=0,0,C40/(C40+D40))
B42: ARPU（全用戶月均） | C42: =C8*C41 | D42: =C8*D41 | E42: =C8*E41
B44: 營運成本假設
B45: 項目 | C45: Year 1 | D45: Year 2 | E45: Year 3
B46: 月固定成本 | C46: 160000 | D46: 350000 | E46: 700000
...

Sheet 單位經濟
B1: 單位經濟模型（自動計算）
B3: ARPPU vs ARPU
B4: ARPPU（付費用戶月均） | C4: =假設參數!C8
B5: 免費→付費轉換率 | C5: =假設參數!C9
B6: ARPU（全用戶月均） | C6: =C4*C5 | D6: =ARPPU × 轉換率
B8: 付費用戶成本結構
B9: COGS（月/付費用戶） | C9: =假設參數!C15
B10: 單位貢獻利潤 | C10: =C4-C9
B11: 貢獻利潤率 | C11: =IF(C4=0,0,C10/C4) | D11: =IF(C11>=0.7,"✅ 健康","⚠️ 偏低")
B13: 客戶生命週期
B14: 加權平均生命週期 | C14: =假設參數!C22 | D14: 個月（原始）
B15: 調整後生命週期 | C15: =假設參數!C24 | D15: 個月（保守值）
B17: LTV（客戶終身價值）
B18: LTV | C18: =C10*C15 | D18: =貢獻利潤 × 生命週期
B20: CAC（獲客成本）
B21: CAC | C21: =假設參數!C34
B23: 指標 | C23: 數值 | D23: 業界基準 | E23: 判斷
B24: LTV / CAC | C24: =IF(C21=0,0,C18/C21) | D24: >3:1 | E24: =IF(C24>=3,"✅ 健康","❌ 不足")
B25: CAC 回收期（月） | C25: =IF(C10=0,0,C21/C10) | D25: <12 個月 | E25: =IF(C25<=12,"✅ 健康","⚠️ 偏長")
B26: 貢獻利潤率 | C26: =C11 | D26: >70% | E26: =IF(C26>=0.7,"✅ SaaS 健康","⚠️ 偏低")
B28: 敏感度分析
B29: 情境 | C29: 生命週期 | D29: CAC | E29: LTV/CAC
B30: 🟢 樂觀 | C30: 18 | D30: 400 | E30: =IF(D30=0,0,(C4-C9)*C30/D30)
B31: 🟡 基準 | C31: =C15 | D31: =C21 | E31: =IF(D31=0,0,(C4-C9)*C31/D31)
B32: 🔴 悲觀 | C32: 10 | D32: 700 | E32: =IF(D32=0,0,(C4-C9)*C32/D32)

Sheet 三年財務預測
B1: 三年財務預測（自動連動）
B3: 營收預測
B4: 項目 | C4: Year 1 | D4: Year 2 | E4: Year 3
B5: 付費用戶數（年底） | C5: =假設參數!C38 | D5: =假設參數!C39 | E5: =假設參數!C40
B6: 免費用戶數（年底） | C6: =假設參數!D38 | D6: =假設參數!D39 | E6: =假設參數!D40
B7: 全部用戶數（年底） | C7: =C5+C6 | D7: =D5+D6 | E7: =E5+E6
B8: 轉換率 | C8: =IF(C7=0,0,C5/C7) | D8: =IF(D7=0,0,D5/D7) | E8: =IF(E7=0,0,E5/E7)
B9: ARPPU（月） | C9: =假設參數!C8 | D9: =假設參數!C8 | E9: =假設參數!C8
B10: ARPU（全用戶月均） | C10: =C9*C8 | D10: =D9*D8 | E10: =E9*E8
B11: 月均付費用戶 | C11: =ROUND(C5/2*(13-假設參數!E38)/12,0) | D11: =ROUND((C5+D5)/2,0) | E11: =ROUND((D5+E5)/2,0)
B12: 年度營收 | C12: =C11*C9*12 | D12: =D11*D9*12 | E12: =E11*E9*12
B13: 營收成長率 | C13: — | D13: =IF(C12=0,0,(D12-C12)/C12) | E13: =IF(D12=0,0,(E12-D12)/D12)
B15: 成本結構
B16: 項目 | C16: Year 1 | D16: Year 2 | E16: Year 3
B17: 變動成本（COGS） | C17: =C11*假設參數!C15*12 | D17: =D11*假設參數!C15*12 | E17: =E11*假設參數!C15*12
B18: 固定成本（OpEx） | C18: =假設參數!C46*12 | D18: =假設參數!D46*12 | E18: =假設參數!E46*12
B19: 總成本 | C19: =C17+C18 | D19: =D17+D18 | E19: =E17+E18
B21: 損益
B22: 毛利（營收 - COGS） | C22: =C12-C17 | D22: =D12-D17 | E22: =E12-E17
B23: 毛利率 | C23: =IF(C12=0,0,C22/C12) | D23: =IF(D12=0,0,D22/D12) | E23: =IF(E12=0,0,E22/E12)
B24: 淨利/虧損 | C24: =C12-C19 | D24: =D12-D19 | E24: =E12-E19
B25: 淨利率 | C25: =IF(C12=0,0,C24/C12) | D25: =IF(D12=0,0,D24/D12) | E25: =IF(E12=0,0,E24/E12)
B27: 現金流量
B28: 項目 | C28: Year 1 | D28: Year 2 | E28: Year 3
B29: 期初現金 | C29: =假設參數!C47 | D29: =C31 | E29: =D31
B30: 淨現金流 | C30: =C24 | D30: =D24 | E30: =E24
B31: 期末現金 | C31: =C29+C30 | D31: =D29+D30 | E31: =E29+E30
B33: 損益兩平分析
B34: 月固定成本 | C34: =假設參數!C46
B35: 每用戶月貢獻利潤 | C35: =單位經濟!C10
B36: 損益兩平用戶數 | C36: =IF(C35=0,0,ROUNDUP(C34/C35,0)) | D36: 名付費用戶
B38: MRR 里程碑
B39: 時間點 | C39: 付費用戶 | D39: MRR | E39: 說明
B40: M6 | C40: 50 | D40: =C40*假設參數!C8 | E40: 付費方案上線
B41: M12（Year 1 結束） | C41: =假設參數!C38 | D41: =C41*假設參數!C8 | E41: Year 1 目標

Sheet 12個月明細
B1: Year 1 — 逐月營運預測
B3: 月份 | C3: M1 | D3: M2 | E3: M3 | F3: M4 | G3: M5 | H3: M6 | I3: M7 | J3: M8 | K3: M9 | L3: M10 | M3: M11 | N3: M12
B4: 付費用戶 | C4: 0 | D4: 0 | E4: 0 | F4: 0 | G4: 0 | H4: 50 | I4: 125 | J4: 200 | K4: 250 | L4: 300 | M4: 400 | N4: 500
B5: ARPPU | C5: =假設參數!C8 | D5: =假設參數!C8 | E5: =假設參數!C8 | F5: =假設參數!C8 | G5: =假設參數!C8 | H5: =假設參數!C8 | I5: =假設參數!C8 | J5: =假設參數!C8 | K5: =假設參數!C8 | L5: =假設參數!C8 | M5: =假設參數!C8 | N5: =假設參數!C8
B6: 月營收 | C6: =C4*C5 | D6: =D4*D5 | E6: =E4*E5 | F6: =F4*F5 | G6: =G4*G5 | H6: =H4*H5 | I6: =I4*I5 | J6: =J4*J5 | ... N6: =N4*N5
B7: COGS | C7: =C4*假設參數!C15 | D7: =D4*假設參數!C15 | E7: =E4*假設參數!C15 | F7: =F4*假設參數!C15 | G7: =G4*假設參數!C15 | H7: =H4*假設參數!C15 | I7: =I4*假設參數!C15 | J7: =J4*假設參數!C15 | K7: =K4*假設參數!C15 | L7: =L4*假設參數!C15 | M7: =M4*假設參數!C15 | N7: =N4*假設參數!C15
B8: 貢獻利潤 | C8: =C6-C7 | D8: =D6-D7 | E8: =E6-E7 | F8: =F6-F7 | G8: =G6-G7 | H8: =H6-H7 | I8: =I6-I7 | J8: =J6-J7 | ... N8: =N6-N7
B9: 固定成本 | C9: =假設參數!C46 | D9: =假設參數!C46 | E9: =假設參數!C46 | F9: =假設參數!C46 | G9: =假設參數!C46 | H9: =假設參數!C46 | I9: =假設參數!C46 | J9: =假設參數!C46 | K9: =假設參數!C46 | L9: =假設參數!C46 | M9: =假設參數!C46 | N9: =假設參數!C46
B10: 月損益 | C10: =C8-C9 | D10: =D8-D9 | E10: =E8-E9 | F10: =F8-F9 | G10: =G8-G9 | H10: =H8-H9 | I10: =I8-I9 | J10: =J8-J9 | ... N10: =N8-N9
B11: 累計損益 | C11: =C10 | D11: =C11+D10 | E11: =D11+E10 | F11: =E11+F10 | G11: =F11+G10 | H11: =G11+H10 | I11: =H11+I10 | J11: =I11+J10 | K11: =J11+K10 | ... N11: =M11+N10
B12: MRR | C12: =C6 | D12: =D6 | E12: =E6 | F12: =F6 | G12: =G6 | H12: =H6 | I12: =I6 | J12: =J6 | ... N12: =N6
B14: Year 1 摘要
B15: 全年營收合計 | C15: =SUM(C6:N6)
B16: M6 MRR | C16: =H6
B17: M12 MRR | C17: =N6
